INFO:app:Default model not found locally, download started...
INFO:app:Default model downloaded, Log_reg_shot_dist_only version 1.17.0
INFO:app:Default model downloaded downloaded
INFO:app:{'url': ''}
INFO:werkzeug:127.0.0.1 - - [04/Dec/2023 23:16:20] "POST /predict HTTP/1.1" 200 -
INFO:app:Default model loaded, Log_reg_shot_dist_only version 1.17.0
ERROR:app:Exception on /check [GET]
Traceback (most recent call last):
  File "C:\Users\yujd1\AppData\Roaming\Python\Python310\site-packages\flask\app.py", line 2073, in wsgi_app
    response = self.full_dispatch_request()
  File "C:\Users\yujd1\AppData\Roaming\Python\Python310\site-packages\flask\app.py", line 1519, in full_dispatch_request
    rv = self.handle_user_exception(e)
  File "C:\Users\yujd1\AppData\Roaming\Python\Python310\site-packages\flask\app.py", line 1517, in full_dispatch_request
    rv = self.dispatch_request()
  File "C:\Users\yujd1\AppData\Roaming\Python\Python310\site-packages\flask\app.py", line 1503, in dispatch_request
    return self.ensure_sync(self.view_functions[rule.endpoint])(**req.view_args)
  File "C:\Users\yujd1\Documents\GitHub\datascience\milestone3\serving\app.py", line 56, in check
    return jsonify(loaded_model.feature_names_in_)
AttributeError: 'NoneType' object has no attribute 'feature_names_in_'
INFO:werkzeug:127.0.0.1 - - [04/Dec/2023 23:33:39] "[35m[1mGET /check?model_name=qq&version=pp HTTP/1.1[0m" 500 -
ERROR:app:Exception on /check [GET]
Traceback (most recent call last):
  File "C:\Users\yujd1\AppData\Roaming\Python\Python310\site-packages\flask\app.py", line 2073, in wsgi_app
    response = self.full_dispatch_request()
  File "C:\Users\yujd1\AppData\Roaming\Python\Python310\site-packages\flask\app.py", line 1519, in full_dispatch_request
    rv = self.handle_user_exception(e)
  File "C:\Users\yujd1\AppData\Roaming\Python\Python310\site-packages\flask\app.py", line 1517, in full_dispatch_request
    rv = self.dispatch_request()
  File "C:\Users\yujd1\AppData\Roaming\Python\Python310\site-packages\flask\app.py", line 1503, in dispatch_request
    return self.ensure_sync(self.view_functions[rule.endpoint])(**req.view_args)
  File "C:\Users\yujd1\Documents\GitHub\datascience\milestone3\serving\app.py", line 56, in check
    return jsonify(loaded_model.feature_names_in_)
AttributeError: 'NoneType' object has no attribute 'feature_names_in_'
INFO:werkzeug:127.0.0.1 - - [04/Dec/2023 23:33:48] "[35m[1mGET /check HTTP/1.1[0m" 500 -
INFO:app:Default model loaded, Log_reg_shot_dist_only version 1.17.0
ERROR:app:Exception on /check [GET]
Traceback (most recent call last):
  File "C:\Users\yujd1\AppData\Roaming\Python\Python310\site-packages\flask\app.py", line 2073, in wsgi_app
    response = self.full_dispatch_request()
  File "C:\Users\yujd1\AppData\Roaming\Python\Python310\site-packages\flask\app.py", line 1519, in full_dispatch_request
    rv = self.handle_user_exception(e)
  File "C:\Users\yujd1\AppData\Roaming\Python\Python310\site-packages\flask\app.py", line 1517, in full_dispatch_request
    rv = self.dispatch_request()
  File "C:\Users\yujd1\AppData\Roaming\Python\Python310\site-packages\flask\app.py", line 1503, in dispatch_request
    return self.ensure_sync(self.view_functions[rule.endpoint])(**req.view_args)
  File "C:\Users\yujd1\Documents\GitHub\datascience\milestone3\serving\app.py", line 56, in check
    return loaded_model.feature_names_in_
AttributeError: 'NoneType' object has no attribute 'feature_names_in_'
INFO:werkzeug:127.0.0.1 - - [04/Dec/2023 23:36:39] "[35m[1mGET /check HTTP/1.1[0m" 500 -
ERROR:app:Exception on /check [GET]
Traceback (most recent call last):
  File "C:\Users\yujd1\AppData\Roaming\Python\Python310\site-packages\flask\app.py", line 2073, in wsgi_app
    response = self.full_dispatch_request()
  File "C:\Users\yujd1\AppData\Roaming\Python\Python310\site-packages\flask\app.py", line 1519, in full_dispatch_request
    rv = self.handle_user_exception(e)
  File "C:\Users\yujd1\AppData\Roaming\Python\Python310\site-packages\flask\app.py", line 1517, in full_dispatch_request
    rv = self.dispatch_request()
  File "C:\Users\yujd1\AppData\Roaming\Python\Python310\site-packages\flask\app.py", line 1503, in dispatch_request
    return self.ensure_sync(self.view_functions[rule.endpoint])(**req.view_args)
  File "C:\Users\yujd1\Documents\GitHub\datascience\milestone3\serving\app.py", line 56, in check
    return loaded_model.feature_names_in_
AttributeError: 'NoneType' object has no attribute 'feature_names_in_'
INFO:werkzeug:127.0.0.1 - - [04/Dec/2023 23:36:44] "[35m[1mGET /check HTTP/1.1[0m" 500 -
